14:05:59.099978 INFO [otestpointd] discovery service listening on tcp://10.99.0.6:8881
14:05:59.585534 INFO [otestpoint-probe/node-6/0/manager] available probes: EMANE.PhysicalLayer.Counters.General EMANE.PhysicalLayer.Tables.Events EMANE.PhysicalLayer.Tables.Status
14:05:59.586751 INFO [otestpoint-probe/node-6/1/manager] available probes: EMANE.RFPipe.Counters.General EMANE.RFPipe.Tables.Events EMANE.RFPipe.Tables.Neighbor EMANE.RFPipe.Tables.Status
14:05:59.587797 INFO [otestpoint-probe/node-6/2/manager] available probes: EMANE.VirtualTransport.Counters.General EMANE.VirtualTransport.Tables.Events EMANE.VirtualTransport.Tables.Status
14:05:59.588824 ERROR [otestpointd/node-6/0/container] Traceback (most recent call last):

  File "/usr/lib/python2.7/dist-packages/otestpoint/emane/probebase.py", line 195, in start
    raise ProbeException("unable to connect to %s:%d" % (self._address,self._port))

ProbeException: unable to connect to localhost:47000

14:05:59.589675 ERROR [otestpointd/node-6/1/container] Traceback (most recent call last):

  File "/usr/lib/python2.7/dist-packages/otestpoint/emane/probebase.py", line 195, in start
    raise ProbeException("unable to connect to %s:%d" % (self._address,self._port))

ProbeException: unable to connect to localhost:47000

14:05:59.590291 ERROR [otestpointd/node-6/2/container] Traceback (most recent call last):

  File "/usr/lib/python2.7/dist-packages/otestpoint/emane/probebase.py", line 195, in start
    raise ProbeException("unable to connect to %s:%d" % (self._address,self._port))

ProbeException: unable to connect to localhost:47000

